Workbook
Name CPLO: 'EE 101'!$E$14:$K$14
Name CPLO: 'EE 201'!$E$14:$K$14
Name CPLO: 'EE 202'!$E$14:$K$14
Name CPLO: 'EE 211'!$E$14:$K$14
Name CPLO: 'EE 221'!$E$14:$K$14
Name CPLO: 'EE 231'!$E$14:$K$14
Name CPLO: 'EE 304'!$E$14:$K$14
Name CPLO: 'EE 305'!$E$14:$K$14
Name CPLO: 'EE 312'!$E$14:$K$14
Name CPLO: 'EE 322'!$E$14:$K$14
Name CPLO: 'EE 332'!$E$14:$K$14
Name CPLO: 'EE 341'!$E$14:$K$14
Name CPLO: 'EE 351'!$E$14:$K$14
Name CPLO: 'EE 403'!$E$14:$K$14
Name CPLO: 'EE 414'!$E$14:$K$14
Name CPLO: 'EE 415'!$E$14:$K$14
Name CPLO: 'EE 416'!$E$14:$K$14
Name CPLO: 'EE 423'!$E$14:$K$14
Name CPLO: 'EE 424'!$E$14:$K$14
Name CPLO: 'EE 425'!$E$14:$K$14
Name CPLO: 'EE 426'!$E$14:$K$14
Name CPLO: 'EE 433'!$E$14:$K$14
Name CPLO: 'EE 434'!$E$14:$K$14
Name CPLO: 'EE 435'!$E$14:$K$14
Name CPLO: 'EE 436'!$E$14:$K$14
Name CPLO: 'EE 442'!$E$14:$K$14
Name CPLO: 'EE 456'!$E$14:$K$14
Name CPLO: 'EE 490'!$E$14:$K$14
Name CPLO: 'EE 492'!$E$14:$K$14
Name CPLO: 'EE 499'!$E$14:$K$14
Name CPLO: #REF!

Sheet Course-PEO
C1: PEO1 | D1: PEO2 | E1: PEO3
A2: Course Title | B2: Course Code | C2: Technical Competence and Innovation | D2: Ethical, Professional, and Sustainable Responsibilities | E2: Leadership and Teamwork
A3: Computer Programming for Engineers | B3: EE 101 | C3: x | E3: x
A4: Introduction to Circuits | B4: EE 201 | C4: x | D4: x
A5: Electronic Fundamentals | B5: EE 211 | C5: x | D5: x
A6: Logic Design | B6: EE 221 | C6: x | D6: x | E6: x
A7: Signals and Systems | B7: EE 231 | C7: x | E7: x
A8: Circuit Analysis | B8: EE 202 | C8: x
A9: Electronic Engineering | B9: EE 312 | C9: x
A10: Microprocessors Design | B10: EE 322 | C10: x | D10: x | E10: x
A11: Electromagnetics Fundamental | B11: EE 341 | C11: x
A12: Control Systems | B12: EE 332 | C12: x | E12: x
A13: Communication Systems | B13: EE 351 | C13: x | E13: x
A14: Power Electronics | B14: EE 305 | C14: x | D14: x | E14: x
A15: Electrical Machines | B15: EE 304 | C15: x | D15: x
A16: Power Systems | B16: EE 403 | C16: x
A17: Senior Design Project | B17: EE 490 | C17: x | D17: x | E17: x
A18: Cooperative Training | B18: EE 492 | C18: x | D18: x | E18: x
C20: PEO1 | D20: PEO2 | E20: PEO3
A21: Course Title | B21: Course Code | C21: Technical Competence and Innovation | D21: Ethical, Professional, and Sustainable Responsibilities | E21: Leadership and Teamwork
A22: Calculus I | B22: MATH 111 | C22: x
A23: Calculus II | B23: MATH 113 | C23: x
A24: Engineering Mathematics | B24: MATH 215 | C24: x | E24: x
A25: Differential Equations | B25: MATH 225 | C25: x
A26: Linear Algebra | B26: MATH 223 | C26: x
A27: Physics I | B27: PHY 105 | C27: x
A28: Physics II | B28: PHY 205 | C28: x
A29: General Chemistry | B29: CHM 101 | C29: x | D29: x
A30: Statistics & Probability | B30: STAT 101 | C30: x | E30: x

Sheet PEOs
C1: PEO1 | D1: PEO2 | E1: PEO3
A2: SO | B2: Student Outcome (SO) | C2: Technical Competence and Innovation- EE graduates will apply electrical engineering knowledge and skills to design solutions, solve complex problems, and pursue graduate studies and research, demonstrating creativity and innovation. | D2: Ethical, Professional, and Sustainable Responsibilities- EE graduates will uphold ethical standards, commit to sustainability, and pursue lifelong learning. | E2: Leadership and Teamwork- EE graduates will demonstrate leadership, critical thinking, decision-making, and teamwork, contributing positively to their organizations and society.
A3: 1 | B3: An ability to identify, formulate, and solve complex engineering problems by applying principles of engineering, science, and mathematics. | C3: x
A4: 2 | B4: An ability to apply engineering design to produce solutions that meet specified needs with consideration of public health, safety, and welfare, as well as global, cultural, social, environmental, and economic factors. | C4: x
A5: 3 | B5: An ability to communicate effectively with a range of audiences. | C5: x | E5: x
A6: 6 | B6: An ability to develop and conduct appropriate experimentation, analyze and interpret data, and use engineering judgment to draw conclusions. | C6: x
A7: 4 | B7: An ability to recognize ethical and professional responsibilities in engineering situations and make informed judgments, which must consider the impact of engineering solutions in global, economic, environmental, and societal contexts. | D7: x
A8: 5 | B8: An ability to function effectively on a team whose members together provide leadership, create a collaborative and inclusive environment, establish goals, plan tasks, and meet objectives. | E8: x
A9: 7 | B9: An ability to acquire and apply new knowledge as needed, using appropriate learning strategies. | D9: x

Sheet PLOs
A1: NQF Learning Domains | C1: PLO | D1: Program Learning Outcome (PLO) / Student Outcome (SO)
A2: Knowledge & Understanding | B2: K1 | C2: 1 | D2: An ability to identify, formulate, and solve complex engineering problems by applying principles of engineering, science, and mathematics.
A3: Skills | B3: S1 | C3: 2 | D3: An ability to apply engineering design to produce solutions that meet specified needs with consideration of public health, safety, and welfare, as well as global, cultural, social, environmental, and economic factors.
B4: S2 | C4: 3 | D4: An ability to communicate effectively with a range of audiences.
B5: S3 | C5: 6 | D5: An ability to develop and conduct appropriate experimentation, analyze and interpret data, and use engineering judgment to draw conclusions.
A6: Values, autonomy and responsibility | B6: V1 | C6: 4 | D6: An ability to recognize ethical and professional responsibilities in engineering situations and make informed judgments, which must consider the impact of engineering solutions in global, economic, environmental, and societal contexts.
B7: V2 | C7: 5 | D7: An ability to function effectively on a team whose members together provide leadership, create a collaborative and inclusive environment, establish goals, plan tasks, and meet objectives.
B8: V3 | C8: 7 | D8: An ability to acquire and apply new knowledge as needed, using appropriate learning strategies.

Sheet ABET
A1: Course Code: | B1: Id | C1: Course Title | D1: Type: | E1: Perf. Level: | F1: R/E: | G1: Credit Hours: | H1: Contact Hours: | I1: Pre-req.: | J1: Co-req.: | K1: Level | L1: Year | M1: Program | N1: Department | O1: Version | P1: Revision Date | Q1: COUNCIL /COMMITTEE | R1: REFERENCE NO. | S1: Date of Approval | T1: Instructor | U1: Course Description | V1: Textbook | W1: Ref. 1 | X1: Ref. 2 | Y1: Ref. 3 | Z1: CLO 1 | AA1: CLO 2 | AB1: CLO 3 | AC1: CLO 4 | AD1: CLO 5 | AE1: CLO 6 | AF1: CLO 7 | AG1: CLO 8 | AH1: CLO 9 | AI1: CLO 10 | AJ1: MPLO1 | AK1: MPLO2 | AL1: MPLO3 | AM1: MPLO4 | AN1: MPLO5 | AO1: MPLO6 | AP1: MPLO7 | AQ1: MPLO8 | AR1: MPLO9 | AS1: MPLO10 | AT1: Top1 | AU1: Top2 | AV1: Top3 | AW1: Top4 | AX1: Top5 | AY1: Top6 | AZ1: Top7 | BA1: Top8 | BB1: Top9 | BC1: Top10 | BD1: O1 | BE1: O2 | BF1: O3 | BG1: Top1 CH | BH1: Top2 CH | BI1: Top3 CH | BJ1: Top4 CH | BK1: Top5 CH | BL1: Top6 CH | BM1: Top7 CH | BN1: Top8 CH | BO1: Top9 CH | BP1: Top10 CH | BQ1: CLO 1 TS | BR1: CLO 2 TS | BS1: CLO 3 TS | BT1: CLO 4 TS | BU1: CLO 5 TS | BV1: CLO 6 TS | BW1: CLO 7 TS | BX1: CLO 8 TS | BY1: CLO 9 TS | BZ1: CLO 10 TS | CA1: CLO 1 AM | CB1: CLO 2 AM | CC1: CLO 3 AM | CD1: CLO 4 AM | CE1: CLO 5 AM | CF1: CLO 6 AM | CG1: CLO 7 AM | CH1: CLO 8 AM | CI1: CLO 9 AM | CJ1: CLO 10 AM | CK1: TotalCH | CL1: TutHrs | CM1: LabHrs | CN1: TopicHrs
A2: ='EE 101'!A2 -> EE 101 | B2: ='EE 101'!B2 -> 11 | C2: ='EE 101'!C2 -> Computer Programming for Engineering | D2: ='EE 101'!D2 -> College | E2: ='EE 101'!E2 -> I | F2: ='EE 101'!F2 -> Required | G2: ='EE 101'!G2 -> 4 | H2: ='EE 101'!H2 -> 6 | ... CN2: ='EE 101'!CN2 -> 90
A3: ='EE 201'!A2 -> EE 201 | B3: ='EE 201'!B2 -> 12 | C3: ='EE 201'!C2 -> Introduction to Circuits | D3: ='EE 201'!D2 -> Program | E3: ='EE 201'!E2 -> I | F3: ='EE 201'!F2 -> Required | G3: ='EE 201'!G2 -> 4 | H3: ='EE 201'!H2 -> 6 | ... CN3: ='EE 201'!CN2 -> 90
A4: ='EE 211'!A2 -> EE 211 | B4: ='EE 211'!B2 -> 13 | C4: ='EE 211'!C2 -> Electronic Fundamentals | D4: ='EE 211'!D2 -> Program | E4: ='EE 211'!E2 -> I | F4: ='EE 211'!F2 -> Required | G4: ='EE 211'!G2 -> 4 | H4: ='EE 211'!H2 -> 6 | ... CN4: ='EE 211'!CN2 -> 90
A5: ='EE 221'!A2 -> EE 221 | B5: ='EE 221'!B2 -> 14 | C5: ='EE 221'!C2 -> Logic Design | D5: ='EE 221'!D2 -> Program | E5: ='EE 221'!E2 -> I | F5: ='EE 221'!F2 -> Required | G5: ='EE 221'!G2 -> 4 | H5: ='EE 221'!H2 -> 6 | ... CN5: ='EE 221'!CN2 -> 90
A6: ='EE 231'!A2 -> EE 231 | B6: ='EE 231'!B2 -> 15 | C6: ='EE 231'!C2 -> Signals and Systems | D6: ='EE 231'!D2 -> Program | E6: ='EE 231'!E2 -> I | F6: ='EE 231'!F2 -> Required | G6: ='EE 231'!G2 -> 3 | H6: ='EE 231'!H2 -> 4 | ... CN6: ='EE 231'!CN2 -> 60
A7: ='EE 202'!A2 -> EE 202 | B7: ='EE 202'!B2 -> 16 | C7: ='EE 202'!C2 -> Circuit Analysis | D7: ='EE 202'!D2 -> Program | E7: ='EE 202'!E2 -> I | F7: ='EE 202'!F2 -> Required | G7: ='EE 202'!G2 -> 3 | H7: ='EE 202'!H2 -> 4 | ... CN7: ='EE 202'!CN2 -> 60
A8: ='EE 312'!A2 -> EE 312 | B8: ='EE 312'!B2 -> 17 | C8: ='EE 312'!C2 -> Electronic Engineering | D8: ='EE 312'!D2 -> Program | E8: ='EE 312'!E2 -> P | F8: ='EE 312'!F2 -> Required | G8: ='EE 312'!G2 -> 3 | H8: ='EE 312'!H2 -> 4 | ... CN8: ='EE 312'!CN2 -> 60
A9: ='EE 322'!A2 -> EE 322 | B9: ='EE 322'!B2 -> 18 | C9: ='EE 322'!C2 -> Microprocessors Design | D9: ='EE 322'!D2 -> Program | E9: ='EE 322'!E2 -> P | F9: ='EE 322'!F2 -> Required | G9: ='EE 322'!G2 -> 4 | H9: ='EE 322'!H2 -> 6 | ... CN9: ='EE 322'!CN2 -> 90
A10: ='EE 341'!A2 -> EE 341 | B10: ='EE 341'!B2 -> 19 | C10: ='EE 341'!C2 -> Electromagnetics Fundamental | D10: ='EE 341'!D2 -> Program | E10: ='EE 341'!E2 -> P | F10: ='EE 341'!F2 -> Required | G10: ='EE 341'!G2 -> 3 | H10: ='EE 341'!H2 -> 4 | ... CN10: ='EE 341'!CN2 -> 60
A11: ='EE 332'!A2 -> EE 332 | B11: ='EE 332'!B2 -> 20 | C11: ='EE 332'!C2 -> Control Systems | D11: ='EE 332'!D2 -> Program | E11: ='EE 332'!E2 -> P | F11: ='EE 332'!F2 -> Required | G11: ='EE 332'!G2 -> 3 | H11: ='EE 332'!H2 -> 4 | ... CN11: ='EE 332'!CN2 -> 60
A12: ='EE 351'!A2 -> EE 351 | B12: ='EE 351'!B2 -> 21 | C12: ='EE 351'!C2 -> Communication Systems | D12: ='EE 351'!D2 -> Program | E12: ='EE 351'!E2 -> P | F12: ='EE 351'!F2 -> Required | G12: ='EE 351'!G2 -> 4 | H12: ='EE 351'!H2 -> 6 | ... CN12: ='EE 351'!CN2 -> 90
A13: ='EE 305'!A2 -> EE 305 | B13: ='EE 305'!B2 -> 22 | C13: ='EE 305'!C2 -> Power Electronics | D13: ='EE 305'!D2 -> Program | E13: ='EE 305'!E2 -> P | F13: ='EE 305'!F2 -> Required | G13: ='EE 305'!G2 -> 4 | H13: ='EE 305'!H2 -> 6 | ... CN13: ='EE 305'!CN2 -> 90
A14: ='EE 304'!A2 -> EE 304 | B14: ='EE 304'!B2 -> 23 | C14: ='EE 304'!C2 -> Electrical Machines | D14: ='EE 304'!D2 -> Program | E14: ='EE 304'!E2 -> P | F14: ='EE 304'!F2 -> Required | G14: ='EE 304'!G2 -> 3 | H14: ='EE 304'!H2 -> 4 | ... CN14: ='EE 304'!CN2 -> 60
A15: ='EE 403'!A2 -> EE 403 | B15: ='EE 403'!B2 -> 24 | C15: ='EE 403'!C2 -> Power Systems | D15: ='EE 403'!D2 -> Program | E15: ='EE 403'!E2 -> M | F15: ='EE 403'!F2 -> Required | G15: ='EE 403'!G2 -> 3 | H15: ='EE 403'!H2 -> 4 | ... CN15: ='EE 403'!CN2 -> 60
A16: ='EE 490'!A2 -> EE 490 | B16: ='EE 490'!B2 -> 25 | C16: ='EE 490'!C2 -> Senior Design Project | D16: ='EE 490'!D2 -> Capstone | E16: ='EE 490'!E2 -> M | F16: ='EE 490'!F2 -> Required | G16: ='EE 490'!G2 -> 3 | H16: ='EE 490'!H2 -> 3 | ... CN16: ='EE 490'!CN2 -> 45
A17: ='EE 492'!A2 -> EE 492 | B17: ='EE 492'!B2 -> 26 | C17: ='EE 492'!C2 -> Cooperative Training | D17: ='EE 492'!D2 -> COOP | E17: ='EE 492'!E2 -> M | F17: ='EE 492'!F2 -> Required | G17: ='EE 492'!G2 -> 10 | H17: ='EE 492'!H2 -> NA | ... CN17: ='EE 492'!CN2 -> 0
A18: ='EE 414'!A2 -> EE 414 | B18: ='EE 414'!B2 -> 27 | C18: ='EE 414'!C2 -> Electrical and Electronic Measurements | D18: ='EE 414'!D2 -> Program | E18: ='EE 414'!E2 -> M | F18: ='EE 414'!F2 -> Elective | G18: ='EE 414'!G2 -> 3 | H18: ='EE 414'!H2 -> 3 | ... CN18: ='EE 414'!CN2 -> 45
A19: ='EE 415'!A2 -> EE 415 | B19: ='EE 415'!B2 -> 28 | C19: ='EE 415'!C2 -> Opto-Electronics | D19: ='EE 415'!D2 -> Program | E19: ='EE 415'!E2 -> M | F19: ='EE 415'!F2 -> Elective | G19: ='EE 415'!G2 -> 3 | H19: ='EE 415'!H2 -> 3 | ... CN19: ='EE 415'!CN2 -> 45
A20: ='EE 416'!A2 -> EE 416 | B20: ='EE 416'!B2 -> 29 | C20: ='EE 416'!C2 -> VLSI Circuits Design | D20: ='EE 416'!D2 -> Program | E20: ='EE 416'!E2 -> M | F20: ='EE 416'!F2 -> Elective | G20: ='EE 416'!G2 -> 3 | H20: ='EE 416'!H2 -> 3 | ... CN20: ='EE 416'!CN2 -> 45
A21: ='EE 423'!A2 -> EE 423 | B21: ='EE 423'!B2 -> 30 | C21: ='EE 423'!C2 -> Data Communication Networks | D21: ='EE 423'!D2 -> Program | E21: ='EE 423'!E2 -> M | F21: ='EE 423'!F2 -> Elective | G21: ='EE 423'!G2 -> 3 | H21: ='EE 423'!H2 -> 3 | ... CN21: ='EE 423'!CN2 -> 45
A22: ='EE 424'!A2 -> EE 424 | B22: ='EE 424'!B2 -> 31 | C22: ='EE 424'!C2 -> Digital Communications | D22: ='EE 424'!D2 -> Program | E22: ='EE 424'!E2 -> M | F22: ='EE 424'!F2 -> Elective | G22: ='EE 424'!G2 -> 3 | H22: ='EE 424'!H2 -> 3 | ... CN22: ='EE 424'!CN2 -> 45
A23: ='EE 425'!A2 -> EE 425 | B23: ='EE 425'!B2 -> 32 | C23: ='EE 425'!C2 -> Wireless Communications Systems | D23: ='EE 425'!D2 -> Program | E23: ='EE 425'!E2 -> M | F23: ='EE 425'!F2 -> Elective | G23: ='EE 425'!G2 -> 3 | H23: ='EE 425'!H2 -> 3 | ... CN23: ='EE 425'!CN2 -> 45
A24: ='EE 426'!A2 -> EE 426 | B24: ='EE 426'!B2 -> 33 | C24: ='EE 426'!C2 -> Antenna and wave propagation | D24: ='EE 426'!D2 -> Program | E24: ='EE 426'!E2 -> M | F24: ='EE 426'!F2 -> Elective | G24: ='EE 426'!G2 -> 3 | H24: ='EE 426'!H2 -> 3 | ... CN24: ='EE 426'!CN2 -> 45
A25: ='EE 433'!A2 -> EE 433 | B25: ='EE 433'!B2 -> 34 | C25: ='EE 433'!C2 -> Mechatronics | D25: ='EE 433'!D2 -> Program | E25: ='EE 433'!E2 -> M | F25: ='EE 433'!F2 -> Elective | G25: ='EE 433'!G2 -> 3 | H25: ='EE 433'!H2 -> 3 | ... CN25: ='EE 433'!CN2 -> 45
A26: ='EE 434'!A2 -> EE 434 | B26: ='EE 434'!B2 -> 35 | C26: ='EE 434'!C2 -> PLC Microcontrollers | D26: ='EE 434'!D2 -> Program | E26: ='EE 434'!E2 -> M | F26: ='EE 434'!F2 -> Elective | G26: ='EE 434'!G2 -> 3 | H26: ='EE 434'!H2 -> 3 | ... CN26: ='EE 434'!CN2 -> 45
A27: ='EE 435'!A2 -> EE 435 | B27: ='EE 435'!B2 -> 36 | C27: ='EE 435'!C2 -> Robotics and Automation | D27: ='EE 435'!D2 -> Program | E27: ='EE 435'!E2 -> M | F27: ='EE 435'!F2 -> Elective | G27: ='EE 435'!G2 -> 3 | H27: ='EE 435'!H2 -> 3 | ... CN27: ='EE 435'!CN2 -> 45
A28: ='EE 436'!A2 -> EE 436 | B28: ='EE 436'!B2 -> 37 | C28: ='EE 436'!C2 -> Artifitial Intellegince | D28: ='EE 436'!D2 -> Program | E28: ='EE 436'!E2 -> M | F28: ='EE 436'!F2 -> Elective | G28: ='EE 436'!G2 -> 3 | H28: ='EE 436'!H2 -> 3 | ... CN28: ='EE 436'!CN2 -> 45
A29: ='EE 442'!A2 -> EE 442 | B29: ='EE 442'!B2 -> 38 | C29: ='EE 442'!C2 -> Digital Signal Processing | D29: ='EE 442'!D2 -> Program | E29: ='EE 442'!E2 -> M | F29: ='EE 442'!F2 -> Elective | G29: ='EE 442'!G2 -> 3 | H29: ='EE 442'!H2 -> 3 | ... CN29: ='EE 442'!CN2 -> 45
A30: ='EE 456'!A2 -> EE 456 | B30: ='EE 456'!B2 -> 39 | C30: ='EE 456'!C2 -> Renewable Energy Engineering | D30: ='EE 456'!D2 -> Program | E30: ='EE 456'!E2 -> M | F30: ='EE 456'!F2 -> Elective | G30: ='EE 456'!G2 -> 3 | H30: ='EE 456'!H2 -> 3 | ... CN30: ='EE 456'!CN2 -> 45
A31: ='EE 499'!A2 -> EE 499 | B31: ='EE 499'!B2 -> 40 | C31: ='EE 499'!C2 -> Special Topics In Electrical and Electronics Engineering | D31: ='EE 499'!D2 -> Program | E31: ='EE 499'!E2 -> M | F31: ='EE 499'!F2 -> Elective | G31: ='EE 499'!G2 -> 3 | H31: ='EE 499'!H2 -> 3 | ... CN31: ='EE 499'!CN2 -> 45

Sheet Mapping
A1: Course Title | B1: Course Code | C1: K1 | D1: S1 | E1: S2 | F1: S3 | G1: V1 | H1: V2 | I1: V3
C2: PLO1 | D2: PLO2 | E2: PLO3 | F2: PLO6 | G2: PLO4 | H2: PLO5 | I2: PLO7
A3: ='EE 101'!C14 -> Computer Programming for Engineering | B3: ='EE 101'!D14 -> EE 101 | C3: ='EE 101'!E14 -> I | D3: ='EE 101'!F14 -> I | E3: ='EE 101'!G14 -> I | F3: ='EE 101'!H14 -> I | G3: ='EE 101'!I14 | H3: ='EE 101'!J14 | I3: ='EE 101'!K14
A4: ='EE 201'!C14 -> Introduction to Circuits | B4: ='EE 201'!D14 -> EE 201 | C4: ='EE 201'!E14 -> I | D4: ='EE 201'!F14 | E4: ='EE 201'!G14 | F4: ='EE 201'!H14 -> I | G4: ='EE 201'!I14 | H4: ='EE 201'!J14 -> I | I4: ='EE 201'!K14
A5: ='EE 211'!C14 -> Electronic Fundamentals | B5: ='EE 211'!D14 -> EE 211 | C5: ='EE 211'!E14 -> I | D5: ='EE 211'!F14 | E5: ='EE 211'!G14 | F5: ='EE 211'!H14 -> I | G5: ='EE 211'!I14 | H5: ='EE 211'!J14 -> I | I5: ='EE 211'!K14
A6: ='EE 221'!C14 -> Logic Design | B6: ='EE 221'!D14 -> EE 221 | C6: ='EE 221'!E14 -> I | D6: ='EE 221'!F14 -> I | E6: ='EE 221'!G14 | F6: ='EE 221'!H14 -> I | G6: ='EE 221'!I14 -> I | H6: ='EE 221'!J14 -> I | I6: ='EE 221'!K14 -> I
A7: ='EE 231'!C14 -> Signals and Systems | B7: ='EE 231'!D14 -> EE 231 | C7: ='EE 231'!E14 -> I | D7: ='EE 231'!F14 -> I | E7: ='EE 231'!G14 -> I | F7: ='EE 231'!H14 -> I | G7: ='EE 231'!I14 | H7: ='EE 231'!J14 | I7: ='EE 231'!K14
A8: ='EE 202'!C14 -> Circuit Analysis | B8: ='EE 202'!D14 -> EE 202 | C8: ='EE 202'!E14 -> I | D8: ='EE 202'!F14 | E8: ='EE 202'!G14 | F8: ='EE 202'!H14 -> I | G8: ='EE 202'!I14 | H8: ='EE 202'!J14 | I8: ='EE 202'!K14
A9: ='EE 312'!C14 -> Electronic Engineering | B9: ='EE 312'!D14 -> EE 312 | C9: ='EE 312'!E14 -> P | D9: ='EE 312'!F14 -> P | E9: ='EE 312'!G14 | F9: ='EE 312'!H14 -> P | G9: ='EE 312'!I14 | H9: ='EE 312'!J14 | I9: ='EE 312'!K14
A10: ='EE 322'!C14 -> Microprocessors Design | B10: ='EE 322'!D14 -> EE 322 | C10: ='EE 322'!E14 -> P | D10: ='EE 322'!F14 -> P | E10: ='EE 322'!G14 -> P | F10: ='EE 322'!H14 | G10: ='EE 322'!I14 -> P | H10: ='EE 322'!J14 | I10: ='EE 322'!K14 -> P
A11: ='EE 341'!C14 -> Electromagnetics Fundamental | B11: ='EE 341'!D14 -> EE 341 | C11: ='EE 341'!E14 -> P | D11: ='EE 341'!F14 -> P | E11: ='EE 341'!G14 | F11: ='EE 341'!H14 -> P | G11: ='EE 341'!I14 | H11: ='EE 341'!J14 | I11: ='EE 341'!K14
A12: ='EE 332'!C14 -> Control Systems | B12: ='EE 332'!D14 -> EE 332 | C12: ='EE 332'!E14 -> P | D12: ='EE 332'!F14 -> P | E12: ='EE 332'!G14 | F12: ='EE 332'!H14 -> P | G12: ='EE 332'!I14 | H12: ='EE 332'!J14 | I12: ='EE 332'!K14 -> P
A13: ='EE 351'!C14 -> Communication Systems | B13: ='EE 351'!D14 -> EE 351 | C13: ='EE 351'!E14 -> P | D13: ='EE 351'!F14 -> P | E13: ='EE 351'!G14 -> P | F13: ='EE 351'!H14 -> P | G13: ='EE 351'!I14 | H13: ='EE 351'!J14 -> P | I13: ='EE 351'!K14
A14: ='EE 305'!C14 -> Power Electronics | B14: ='EE 305'!D14 -> EE 305 | C14: ='EE 305'!E14 -> P | D14: ='EE 305'!F14 -> P | E14: ='EE 305'!G14 | F14: ='EE 305'!H14 | G14: ='EE 305'!I14 -> P | H14: ='EE 305'!J14 | I14: ='EE 305'!K14 -> P
A15: ='EE 304'!C14 -> Electrical Machines | B15: ='EE 304'!D14 -> EE 304 | C15: ='EE 304'!E14 -> P | D15: ='EE 304'!F14 | E15: ='EE 304'!G14 | F15: ='EE 304'!H14 -> P | G15: ='EE 304'!I14 -> P | H15: ='EE 304'!J14 | I15: ='EE 304'!K14
A16: ='EE 403'!C14 -> Power Systems | B16: ='EE 403'!D14 -> EE 403 | C16: ='EE 403'!E14 -> M | D16: ='EE 403'!F14 -> M | E16: ='EE 403'!G14 | F16: ='EE 403'!H14 -> M | G16: ='EE 403'!I14 | H16: ='EE 403'!J14 | I16: ='EE 403'!K14
A17: ='EE 490'!C14 -> Senior Design Project | B17: ='EE 490'!D14 -> EE 490 | C17: ='EE 490'!E14 -> M | D17: ='EE 490'!F14 -> M | E17: ='EE 490'!G14 -> M | F17: ='EE 490'!H14 -> M | G17: ='EE 490'!I14 -> M | H17: ='EE 490'!J14 -> M | I17: ='EE 490'!K14
A18: ='EE 492'!C14 -> Cooperative Training | B18: ='EE 492'!D14 -> EE 492 | C18: ='EE 492'!E14 -> M | D18: ='EE 492'!F14 -> M | E18: ='EE 492'!G14 -> M | F18: ='EE 492'!H14 -> M | G18: ='EE 492'!I14 -> M | H18: ='EE 492'!J14 -> M | I18: ='EE 492'!K14 -> M
A19: PROGRAM ELECTIVE COURSES
A20: ='EE 442'!C14 -> Digital Signal Processing | B20: ='EE 442'!D14 -> EE 442 | C20: ='EE 442'!E14 | D20: ='EE 442'!F14 | E20: ='EE 442'!G14 | F20: ='EE 442'!H14 | G20: ='EE 442'!I14 | H20: ='EE 442'!J14 | I20: ='EE 442'!K14
A21: ='EE 426'!C14 -> Antenna and wave propagation | B21: ='EE 426'!D14 -> EE 426 | C21: ='EE 426'!E14 -> M | D21: ='EE 426'!F14 -> M | E21: ='EE 426'!G14 | F21: ='EE 426'!H14 -> M | G21: ='EE 426'!I14 -> M | H21: ='EE 426'!J14 | I21: ='EE 426'!K14
A22: ='EE 434'!C14 -> PLC Microcontrollers | B22: ='EE 434'!D14 -> EE 434 | C22: ='EE 434'!E14 -> M | D22: ='EE 434'!F14 -> M | E22: ='EE 434'!G14 | F22: ='EE 434'!H14 -> M | G22: ='EE 434'!I14 | H22: ='EE 434'!J14 | I22: ='EE 434'!K14 -> M
A23: ='EE 456'!C14 -> Renewable Energy Engineering | B23: ='EE 456'!D14 -> EE 456 | C23: ='EE 456'!E14 -> M | D23: ='EE 456'!F14 -> M | E23: ='EE 456'!G14 | F23: ='EE 456'!H14 | G23: ='EE 456'!I14 | H23: ='EE 456'!J14 | I23: ='EE 456'!K14 -> M

Sheet EE 101
A1: Course Code: | B1: Id | C1: Course Title | D1: Type: | E1: Perf. Level: | F1: R/E: | G1: Credit Hours: | H1: Contact Hours: | I1: Pre-req.: | J1: Co-req.: | K1: Level | L1: Year | M1: Program | N1: Department | O1: Version | P1: Revision Date | Q1: COUNCIL /COMMITTEE | R1: REFERENCE NO. | S1: Date of Approval | T1: Instructor | U1: Course Description | V1: Textbook | W1: Ref. 1 | X1: Ref. 2 | Y1: Ref. 3 | Z1: CLO 1 | AA1: CLO 2 | AB1: CLO 3 | AC1: CLO 4 | AD1: CLO 5 | AE1: CLO 6 | AF1: CLO 7 | AG1: CLO 8 | AH1: CLO 9 | AI1: CLO 10 | AJ1: MPLO1 | AK1: MPLO2 | AL1: MPLO3 | AM1: MPLO4 | AN1: MPLO5 | AO1: MPLO6 | AP1: MPLO7 | AQ1: MPLO8 | AR1: MPLO9 | AS1: MPLO10 | AT1: Top1 | AU1: Top2 | AV1: Top3 | AW1: Top4 | AX1: Top5 | AY1: Top6 | AZ1: Top7 | BA1: Top8 | BB1: Top9 | BC1: Top10 | BD1: O1 | BE1: O2 | BF1: O3 | BG1: Top1 CH | BH1: Top2 CH | BI1: Top3 CH | BJ1: Top4 CH | BK1: Top5 CH | BL1: Top6 CH | BM1: Top7 CH | BN1: Top8 CH | BO1: Top9 CH | BP1: Top10 CH | BQ1: CLO 1 TS | BR1: CLO 2 TS | BS1: CLO 3 TS | BT1: CLO 4 TS | BU1: CLO 5 TS | BV1: CLO 6 TS | BW1: CLO 7 TS | BX1: CLO 8 TS | BY1: CLO 9 TS | BZ1: CLO 10 TS | CA1: CLO 1 AM | CB1: CLO 2 AM | CC1: CLO 3 AM | CD1: CLO 4 AM | CE1: CLO 5 AM | CF1: CLO 6 AM | CG1: CLO 7 AM | CH1: CLO 8 AM | CI1: CLO 9 AM | CJ1: CLO 10 AM | CK1: TotalCH | CL1: TutHrs | CM1: LabHrs | CN1: TopicHrs
A2: EE 101 | B2: 11 | C2: Computer Programming for Engineering | D2: College | E2: I | F2: Required | G2: 4 | H2: 6 | I2: NA | J2: NA | K2: 1 | L2: 1 | M2: Electrical engineering | N2: Communications and Networks Engineering | O2: 1 | P2: 25-09-2024 | Q2: Departmental Council | R2: 1 | S2: 25-09-2024 | T2: =IF(C15=0,"",C15) -> Dr. Muddesar Iqbal | U2: =IF(C16=0,"",C16) -> This course covers the concept of programming languages in Python. It enables the student to understand and write basic coding based on various operators, functions, logic statements, Strings, tuples, etc., in the Python programming language. In addition, the course covers the basic concept of files and exceptions. | V2: =IF(C17=0,"",C17) -> E Balagurusamy, "Problem Solving and Python Programming", McGraw Hill Education, 2018. | W2: =IF(C18=0,"",C18) | X2: =IF(C19=0,"",C19) | Y2: =IF(C20=0,"",C20) | Z2: =IF(C4=0,"",C4) -> Define fundamental concepts of programming along with problem-solving techniques and analytical thinking. | AA2: =IF(C5=0,"",C5) | AB2: =IF(C6=0,"",C6) | AC2: =IF(C7=0,"",C7) -> Explain the various logic using various operators and expressions. | AD2: =IF(C8=0,"",C8) -> Write a programming code in Python. | AE2: =IF(C9=0,"",C9) -> Examine program code using Python | AF2: =IF(C10=0,"",C10) | AG2: =IF(C11=0,"",C11) | AH2: =IF(C12=0,"",C12) | AI2: =IF(C13=0,"",C13) | AJ2: =D4 -> 1 | AK2: =D5 | AL2: =D6 | AM2: =D7 -> 3 | AN2: =D8 -> 2 | AO2: =D9 -> 6 | AP2: =D10 | AQ2: =D11 | AR2: =D12 | AS2: =D13 | AT2: =IF(C21=0,"",C21) -> Introduction to Digital Computers and Problem-Solving Strategies. | AU2: =IF(C22=0,"",C22) -> Introduction to Python and Its Importance; Getting Started with Python: Input/Output Statements, Basic Structure of Python Programs, Programming Style, Compilation, and Execution. | AV2: =IF(C23=0,"",C23) -> Keywords and Identifiers, Constants, Variables, Data Types, and Python Instructions. | AW2: =IF(C24=0,"",C24) -> Declaration, Assigning Values, Defining Variables, Operators, and Expressions. | AX2: =IF(C25=0,"",C25) -> Managing Input and Output Operations; Decision Making and Branching, Decision Making and Looping. | AY2: =IF(C26=0,"",C26) -> Python Strings, Lists, Tuples, and Dictionaries. | AZ2: =IF(#REF!=0,"",#REF!) -> #REF! | BA2: =IF(C27=0,"",C27) -> Functions: Built-in Functions, User-Defined Functions, Parameters and Arguments, Function Calls, Return Statements, Python Recursive Functions, Anonymous Functions. | BB2: =IF(C28=0,"",C28) -> Files and Exceptions: Text Files, Directories, Exceptions, Exceptions with Arguments, and User-Defined Exceptions. | BC2: =IF(C30=0,"",C30) | BD2: =C31 -> Understand the basics Linux, Microprocessor and Microcontroller Programming concepts. | BE2: =C32 -> Understand the basics of the computer programming language python. | BF2: =C33 -> Write a basic code in the computer programming language python. | BG2: =IF($D21=0,"",$D21) -> 10 | BH2: =IF($D22=0,"",$D22) -> 12 | BI2: =IF($D23=0,"",$D23) -> 12 | BJ2: =IF($D24=0,"",$D24) -> 14 | BK2: =IF($D25=0,"",$D25) -> 12 | BL2: =IF($D26=0,"",$D26) -> 12 | BM2: =IF($D27=0,"",$D27) -> 10 | BN2: =IF($D28=0,"",$D28) -> 8 | BO2: =IF($D29=0,"",$D29) | BP2: =IF($D30=0,"",$D30) | BQ2: =IF($M4=0,"",$M4) -> Lectures, tutorials, group discussions | BR2: =IF($M5=0,"",$M5) | BS2: =IF($M6=0,"",$M6) | BT2: =IF($M7=0,"",$M7) -> Lectures, tutorial, and group discussions | BU2: =IF($M8=0,"",$M8) -> Lectures, tutorial, and group discussions | BV2: =IF($M9=0,"",$M9) -> Lectures, tutorial, and group discussions | BW2: =IF($M10=0,"",$M10) | BX2: =IF($M11=0,"",$M11) | BY2: =IF($M12=0,"",$M12) | BZ2: =IF($M13=0,"",$M13) | CA2: =IF($N4=0,"",$N4) -> HW assignments, quizzes, major exams, and final exam | CB2: =IF($N5=0,"",$N5) | CC2: =IF($N6=0,"",$N6) | CD2: =IF($N7=0,"",$N7) -> HW assignments, quizzes, major exams, and final exam | CE2: =IF($N8=0,"",$N8) -> HW assignments, quizzes, major exams, and final exam | CF2: =IF($N9=0,"",$N9) -> HW assignments, quizzes, major exams, and final exam | CG2: =IF($N10=0,"",$N10) | CH2: =IF($N11=0,"",$N11) | CI2: =IF($N12=0,"",$N12) | CJ2: =IF($N13=0,"",$N13) | CK2: =H2*15 -> 90 | CL2: =IF(H2>3,15,"") -> 15 | CM2: =IF(G2=4,30,"") -> 30 | CN2: =E30 -> 90
A3: Course Learning Outcomes | D3: Aligned PLOs | E3: PLO1 | F3: PLO2 | G3: PLO3 | H3: PLO6 | I3: PLO4 | J3: PLO5 | K3: PLO7 | M3: Teaching Strategy | N3: Assessment Method | BH3: =IF(E22=0,"",E22)
A4: Knowledge and understanding | B4: 1.1 | C4: Define fundamental concepts of programming along with problem-solving techniques and analytical thinking. | D4: =IF(E4=TRUE,"1","") -> 1 | E4: TRUE | F4: FALSE | H4: FALSE | I4: FALSE | J4: FALSE | M4: =IF(C4=0,"","Lectures, tutorials, group discussions") -> Lectures, tutorials, group discussions | N4: =IF(C4=0,"","HW assignments, quizzes, major exams, and final exam") -> HW assignments, quizzes, major exams, and final exam | BH4: =IF(E23=0,"",E23)
D5: =IF(E5=TRUE,"1","") | E5: FALSE | F5: FALSE | G5: FALSE | H5: FALSE | I5: FALSE | J5: FALSE | K5: FALSE | M5: =IF(C5=0,"","Lectures, tutorial, and group discussions") | N5: =IF(C5=0,"","HW assignments, quizzes, major exams, and final exam") | BH5: =IF(E24=0,"",E24)
D6: =IF(E6=TRUE,"1","") | E6: FALSE | F6: FALSE | G6: FALSE | H6: FALSE | I6: FALSE | J6: FALSE | K6: FALSE | M6: =IF(C6=0,"","Lectures, tutorial, and group discussions") | N6: =IF(C6=0,"","HW assignments, quizzes, major exams, and final exam") | BH6: =IF(E25=0,"",E25)
A7: Skills | B7: 2.1 | C7: Explain the various logic using various operators and expressions. | D7: =CONCATENATE(IF(F7=TRUE,"2",""),IF(AND(G7=TRUE,F7=TRUE),", ",""),IF(G7=TRUE,"3",""),IF(AND(H7=TRUE,COUNTIF(F7:G7,TRUE)>0),", ",""),IF(H7=TRUE,"6","")) -> 3 | E7: FALSE | F7: FALSE | G7: TRUE | H7: FALSE | I7: FALSE | J7: FALSE | K7: FALSE | M7: =IF(C7=0,"","Lectures, tutorial, and group discussions") -> Lectures, tutorial, and group discussions | N7: =IF(C7=0,"","HW assignments, quizzes, major exams, and final exam") -> HW assignments, quizzes, major exams, and final exam | BH7: =IF(E26=0,"",E26)
B8: 2.2 | C8: Write a programming code in Python. | D8: =CONCATENATE(IF(F8=TRUE,"2",""),IF(AND(G8=TRUE,F8=TRUE),", ",""),IF(G8=TRUE,"3",""),IF(AND(H8=TRUE,COUNTIF(F8:G8,TRUE)>0),", ",""),IF(H8=TRUE,"6","")) -> 2 | E8: FALSE | F8: TRUE | G8: FALSE | H8: FALSE | I8: FALSE | J8: FALSE | K8: FALSE | M8: =IF(C8=0,"","Lectures, tutorial, and group discussions") -> Lectures, tutorial, and group discussions | N8: =IF(C8=0,"","HW assignments, quizzes, major exams, and final exam") -> HW assignments, quizzes, major exams, and final exam | BH8: =IF(E27=0,"",E27)
B9: 2.3 | C9: Examine program code using Python | D9: =CONCATENATE(IF(F9=TRUE,"2",""),IF(AND(G9=TRUE,F9=TRUE),", ",""),IF(G9=TRUE,"3",""),IF(AND(H9=TRUE,COUNTIF(F9:G9,TRUE)>0),", ",""),IF(H9=TRUE,"6","")) -> 6 | E9: FALSE | F9: FALSE | G9: FALSE | H9: TRUE | I9: FALSE | J9: FALSE | K9: FALSE | M9: =IF(C9=0,"","Lectures, tutorial, and group discussions") -> Lectures, tutorial, and group discussions | N9: =IF(C9=0,"","HW assignments, quizzes, major exams, and final exam") -> HW assignments, quizzes, major exams, and final exam | BH9: =IF(E28=0,"",E28)
D10: =CONCATENATE(IF(F10=TRUE,"2",""),IF(AND(G10=TRUE,F10=TRUE),", ",""),IF(G10=TRUE,"3",""),IF(AND(H10=TRUE,COUNTIF(F10:G10,TRUE)>0),", ",""),IF(H10=TRUE,"6","")) | E10: FALSE | F10: FALSE | G10: FALSE | H10: FALSE | I10: FALSE | J10: FALSE | K10: FALSE | M10: =IF(C10=0,"","Lectures, tutorial, and group discussions") | N10: =IF(C10=0,"","HW assignments, quizzes, major exams, and final exam") | BH10: =IF(E29=0,"",E29)
D11: =CONCATENATE(IF(F11=TRUE,"2",""),IF(AND(G11=TRUE,F11=TRUE),", ",""),IF(G11=TRUE,"3",""),IF(AND(H11=TRUE,COUNTIF(F11:G11,TRUE)>0),", ",""),IF(H11=TRUE,"6","")) | E11: FALSE | F11: FALSE | G11: FALSE | H11: FALSE | I11: FALSE | J11: FALSE | K11: FALSE | M11: =IF(C11=0,"","Lectures, tutorial, and group discussions") | N11: =IF(C11=0,"","HW assignments, quizzes, major exams, and final exam") | BH11: =IF(E30=0,"",E30) -> 90
A12: Values, autonomy and responsibility | D12: =CONCATENATE(IF(I12=TRUE,"4",""),IF(AND(J12=TRUE,I12=TRUE),", ",""),IF(J12=TRUE,"5",""),IF(AND(K12=TRUE,COUNTIF(I12:J12,TRUE)>0),", ",""),IF(K12=TRUE,"7","")) | E12: FALSE | F12: FALSE | G12: FALSE | H12: FALSE | I12: FALSE | J12: FALSE | K12: FALSE | M12: =IF(C12=0,"","Lectures, tutorial, and group discussions") | N12: =IF(C12=0,"","HW assignments, quizzes, major exams, and final exam")
D13: =CONCATENATE(IF(I13=TRUE,"4",""),IF(AND(J13=TRUE,I13=TRUE),", ",""),IF(J13=TRUE,"5",""),IF(AND(K13=TRUE,COUNTIF(I13:J13,TRUE)>0),", ",""),IF(K13=TRUE,"7","")) | E13: FALSE | F13: FALSE | G13: FALSE | H13: FALSE | I13: FALSE | J13: FALSE | K13: FALSE | M13: =IF(C13=0,"","Lectures, tutorial, and group discussions") | N13: =IF(C13=0,"","HW assignments, quizzes, major exams, and final exam")
A14: Aligned PLOs | C14: =C2 -> Computer Programming for Engineering | D14: =A2 -> EE 101 | E14: =IF(COUNTIF($E$4:$E$13,TRUE)>0,$E$2,"") -> I | F14: =IF(COUNTIF($F$4:$F$13,TRUE)>0,$E$2,"") -> I | G14: =IF(COUNTIF($G$4:$G$13,TRUE)>0,$E$2,"") -> I | H14: =IF(COUNTIF($H$4:$H$13,TRUE)>0,$E$2,"") -> I | I14: =IF(COUNTIF($I$4:$I$13,TRUE)>0,$E$2,"") | J14: =IF(COUNTIF($J$4:$J$13,TRUE)>0,$E$2,"") | K14: =IF(COUNTIF($K$4:$K$13,TRUE)>0,$E$2,"")
A15: Instructor | C15: Dr. Muddesar Iqbal
A16: Course Description | B16: D1 | C16: This course covers the concept of programming languages in Python. It enables the student to understand and write basic coding based on various operators, functions, logic statements, Strings, tuples, etc., in the Python programming language. In addition, the course covers the basic concept of files and exceptions.
A17: Textbook | B17: TB1 | C17: E Balagurusamy, "Problem Solving and Python Programming", McGraw Hill Education, 2018.
A18: References | B18: R1
B19: R2
B20: R3
A21: Topics | B21: T1 | C21: Introduction to Digital Computers and Problem-Solving Strategies. | D21: 10
B22: T2 | C22: Introduction to Python and Its Importance; Getting Started with Python: Input/Output Statements, Basic Structure of Python Programs, Programming Style, Compilation, and Execution. | D22: 12
B23: T3 | C23: Keywords and Identifiers, Constants, Variables, Data Types, and Python Instructions. | D23: 12
B24: T4 | C24: Declaration, Assigning Values, Defining Variables, Operators, and Expressions. | D24: 14
B25: T5 | C25: Managing Input and Output Operations; Decision Making and Branching, Decision Making and Looping. | D25: 12
B26: T6 | C26: Python Strings, Lists, Tuples, and Dictionaries. | D26: 12
B27: T7 | C27: Functions: Built-in Functions, User-Defined Functions, Parameters and Arguments, Function Calls, Return Statements, Python Recursive Functions, Anonymous Functions. | D27: 10
B28: T8 | C28: Files and Exceptions: Text Files, Directories, Exceptions, Exceptions with Arguments, and User-Defined Exceptions. | D28: 8
B29: T9
B30: T10 | E30: =SUM(D21:D30) -> 90
A31: Objectives | B31: O1 | C31: Understand the basics Linux, Microprocessor and Microcontroller Programming concepts.
B32: O2 | C32: Understand the basics of the computer programming language python.
B33: O3 | C33: Write a basic code in the computer programming language python.

Sheet EE 201
A1: Course Code: | B1: Id | C1: Course Title | D1: Type: | E1: Perf. Level: | F1: R/E: | G1: Credit Hours: | H1: Contact Hours: | I1: Pre-req.: | J1: Co-req.: | K1: Level | L1: Year | M1: Program | N1: Department | O1: Version | P1: Revision Date | Q1: COUNCIL /COMMITTEE | R1: REFERENCE NO. | S1: Date of Approval | T1: Instructor | U1: Course Description | V1: Textbook | W1: Ref. 1 | X1: Ref. 2 | Y1: Ref. 3 | Z1: CLO 1 | AA1: CLO 2 | AB1: CLO 3 | AC1: CLO 4 | AD1: CLO 5 | AE1: CLO 6 | AF1: CLO 7 | AG1: CLO 8 | AH1: CLO 9 | AI1: CLO 10 | AJ1: MPLO1 | AK1: MPLO2 | AL1: MPLO3 | AM1: MPLO4 | AN1: MPLO5 | AO1: MPLO6 | AP1: MPLO7 | AQ1: MPLO8 | AR1: MPLO9 | AS1: MPLO10 | AT1: Top1 | AU1: Top2 | AV1: Top3 | AW1: Top4 | AX1: Top5 | AY1: Top6 | AZ1: Top7 | BA1: Top8 | BB1: Top9 | BC1: Top10 | BD1: O1 | BE1: O2 | BF1: O3 | BG1: Top1 CH | BH1: Top2 CH | BI1: Top3 CH | BJ1: Top4 CH | BK1: Top5 CH | BL1: Top6 CH | BM1: Top7 CH | BN1: Top8 CH | BO1: Top9 CH | BP1: Top10 CH | BQ1: CLO 1 TS | BR1: CLO 2 TS | BS1: CLO 3 TS | BT1: CLO 4 TS | BU1: CLO 5 TS | BV1: CLO 6 TS | BW1: CLO 7 TS | BX1: CLO 8 TS | BY1: CLO 9 TS | BZ1: CLO 10 TS | CA1: CLO 1 AM | CB1: CLO 2 AM | CC1: CLO 3 AM | CD1: CLO 4 AM | CE1: CLO 5 AM | CF1: CLO 6 AM | CG1: CLO 7 AM | CH1: CLO 8 AM | CI1: CLO 9 AM | CJ1: CLO 10 AM | CK1: TotalCH | CL1: TutHrs | CM1: LabHrs | CN1: TopicHrs
A2: EE 201 | B2: 12 | C2: Introduction to Circuits | D2: Program | E2: I | F2: Required | G2: 4 | H2: 6 | I2: PHYS 205, Math113 | J2: NA | K2: 3 | L2: 2 | M2: Electrical engineering | N2: Communications and Networks Engineering | O2: 1 | P2: 25-09-2024 | Q2: Departmental Council | R2: 1 | S2: 25-09-2024 | T2: =IF(C15=0,"",C15) -> Dr. Maged Esmail | U2: =IF(C16=0,"",C16) -> This module provides a comprehensive introduction to both DC and AC circuit principles. Students will begin by reviewing fundamental concepts, including current, voltage, and power. The course then explores series and parallel circuits and delves into Ohm’s Law, Kirchhoff’s Laws, source transformations, bridge networks, and delta/star transformations. Key analysis methods and network theorems are also covered. Additionally, the module revisits inductors and capacitors, introduces sinusoidal sources and the concept of phasors, and details methods for analyzing AC circuits. Practical experience is emphasized through hands-on use of electrical measurement tools such as voltmeters, ammeters, wattmeters, function generators, and oscilloscopes. | V2: =IF(C17=0,"",C17) -> Robert L. Boylestad - Introductory Circuit Analysis (2016, Pearson), 13th Edition | W2: =IF(C18=0,"",C18) | X2: =IF(C19=0,"",C19) | Y2: =IF(C20=0,"",C20) | Z2: =IF(C4=0,"",C4) -> Recognize the main concepts of electrical parameters and their interrelations. | AA2: =IF(C5=0,"",C5) | AB2: =IF(C6=0,"",C6) | AC2: =IF(C7=0,"",C7) -> Analyze DC/AC electric circuits using Ohm`s law, Kirchhoff's circuit laws, and voltage/current divider rules. | AD2: =IF(C8=0,"",C8) -> Analyze DC/AC electric circuits using different analysis techniques such as Mesh, Nodal, and Thevenin. | AE2: =IF(C9=0,"",C9) -> Analyze sinusoidal signals, reactance, admittance, and power using phasor forms. | AF2: =IF(C10=0,"",C10) | AG2: =IF(C11=0,"",C11) | AH2: =IF(C12=0,"",C12) -> Demonstrate DC/AC electric circuits using hardware boards and simulation in group activities. | AI2: =IF(C13=0,"",C13) | AJ2: =D4 -> 1 | AK2: =D5 | AL2: =D6 | AM2: =D7 -> 6 | AN2: =D8 -> 6 | AO2: =D9 -> 6 | AP2: =D10 | AQ2: =D11 | AR2: =D12 -> 5 | AS2: =D13 | AT2: =IF(C21=0,"",C21) -> Introduction, Basic concepts, charge, current, voltage, power, energy, resistance, and Ohm's Law, dissipated power. | AU2: =IF(C22=0,"",C22) -> Introduction, Series, Parallel and Series parallel circuits, Kirchhoff’s laws, voltage division and current distribution principles, voltage and current sources, open and short circuits | AV2: =IF(C23=0,"",C23) -> Mesh and Nodal Analysis, Bridge networks, Y-∆ and ∆-Y conversion | AW2: =IF(C24=0,"",C24) -> Superposition, Thevenin’s and Norton's theorems | AX2: =IF(C25=0,"",C25) -> Review of capacitance and inductance, Generation of AC voltages, parameters of AC. waveforms, average and effective (RMS) values | AY2: =IF(C26=0,"",C26) -> Review of complex number algebra, phasor representation, impedance and admittance. Capacitive and inductive reactance | AZ2: =IF(C27=0,"",C27) -> Examples of analysis methods for AC circuits | BA2: =IF(C28=0,"",C28) -> General equation, Resistive circuit, Apparent Power, Inductive circuit and reactive power, Capacitive circuit, The power triangle, The total P, Q, and Power factor correction | BB2: =IF(C29=0,"",C29) | BC2: =IF(C30=0,"",C30) | BD2: =C31 -> Understand the basic linear electric circuits, theories, and concepts. | BE2: =C32 -> Understand circuit theorems and laws of circuit analysis in DC and AC circuits. | BF2: =C33 -> Gain hands-on experience and develop skills in using measurement tools like voltmeters, ammeters, and oscilloscopes while linking theory to practice. | BG2: =IF($D21=0,"",$D21) -> 10 | BH2: =IF($D22=0,"",$D22) -> 12 | BI2: =IF($D23=0,"",$D23) -> 12 | BJ2: =IF($D24=0,"",$D24) -> 12 | BK2: =IF($D25=0,"",$D25) -> 12 | BL2: =IF($D26=0,"",$D26) -> 12 | BM2: =IF($D27=0,"",$D27) -> 10 | BN2: =IF($D28=0,"",$D28) -> 10 | BO2: =IF($D29=0,"",$D29) | BP2: =IF($D30=0,"",$D30) | BQ2: =IF($M4=0,"",$M4) -> Lectures, tutorials, group discussions | BR2: =IF($M5=0,"",$M5) | BS2: =IF($M6=0,"",$M6) | BT2: =IF($M7=0,"",$M7) -> Lectures, tutorial, and group discussions | BU2: =IF($M8=0,"",$M8) -> Lectures, tutorial, and group discussions | BV2: =IF($M9=0,"",$M9) -> Lectures, tutorial, and group discussions | BW2: =IF($M10=0,"",$M10) | BX2: =IF($M11=0,"",$M11) | BY2: =IF($M12=0,"",$M12) -> Lectures, tutorial, and group discussions | BZ2: =IF($M13=0,"",$M13) | CA2: =IF($N4=0,"",$N4) -> HW assignments, quizzes, major exams, and final exam | CB2: =IF($N5=0,"",$N5) | CC2: =IF($N6=0,"",$N6) | CD2: =IF($N7=0,"",$N7) -> HW assignments, quizzes, major exams, and final exam | CE2: =IF($N8=0,"",$N8) -> HW assignments, quizzes, major exams, and final exam | CF2: =IF($N9=0,"",$N9) -> HW assignments, quizzes, major exams, and final exam | CG2: =IF($N10=0,"",$N10) | CH2: =IF($N11=0,"",$N11) | CI2: =IF($N12=0,"",$N12) -> HW assignments, quizzes, major exams, and final exam | CJ2: =IF($N13=0,"",$N13) | CK2: =H2*15 -> 90 | CL2: =IF(H2>3,15,"") -> 15 | CM2: =IF(G2=4,30,"") -> 30 | CN2: =E30 -> 90
A3: Course Learning Outcomes | D3: Aligned PLOs | E3: PLO1 | F3: PLO2 | G3: PLO3 | H3: PLO6 | I3: PLO4 | J3: PLO5 | K3: PLO7 | M3: Teaching Strategy | N3: Assessment Method | BH3: =IF(E22=0,"",E22)
A4: Knowledge and understanding | B4: 1.1 | C4: Recognize the main concepts of electrical parameters and their interrelations. | D4: =IF(E4=TRUE,"1","") -> 1 | E4: TRUE | F4: FALSE | H4: FALSE | I4: FALSE | J4: FALSE | M4: =IF(C4=0,"","Lectures, tutorials, group discussions") -> Lectures, tutorials, group discussions | N4: =IF(C4=0,"","HW assignments, quizzes, major exams, and final exam") -> HW assignments, quizzes, major exams, and final exam | BH4: =IF(E23=0,"",E23)
D5: =IF(E5=TRUE,"1","") | E5: FALSE | F5: FALSE | G5: FALSE | H5: FALSE | I5: FALSE | J5: FALSE | K5: FALSE | M5: =IF(C5=0,"","Lectures, tutorial, and group discussions") | N5: =IF(C5=0,"","HW assignments, quizzes, major exams, and final exam") | BH5: =IF(E24=0,"",E24)
D6: =IF(E6=TRUE,"1","") | E6: FALSE | F6: FALSE | G6: FALSE | H6: FALSE | I6: FALSE | J6: FALSE | K6: FALSE | M6: =IF(C6=0,"","Lectures, tutorial, and group discussions") | N6: =IF(C6=0,"","HW assignments, quizzes, major exams, and final exam") | BH6: =IF(E25=0,"",E25)
A7: Skills | B7: 2.1 | C7: Analyze DC/AC electric circuits using Ohm`s law, Kirchhoff's circuit laws, and voltage/current divider rules. | D7: =CONCATENATE(IF(F7=TRUE,"2",""),IF(AND(G7=TRUE,F7=TRUE),", ",""),IF(G7=TRUE,"3",""),IF(AND(H7=TRUE,COUNTIF(F7:G7,TRUE)>0),", ",""),IF(H7=TRUE,"6","")) -> 6 | E7: FALSE | F7: FALSE | G7: FALSE | H7: TRUE | I7: FALSE | J7: FALSE | K7: FALSE | M7: =IF(C7=0,"","Lectures, tutorial, and group discussions") -> Lectures, tutorial, and group discussions | N7: =IF(C7=0,"","HW assignments, quizzes, major exams, and final exam") -> HW assignments, quizzes, major exams, and final exam | BH7: =IF(E26=0,"",E26)
B8: 2.2 | C8: Analyze DC/AC electric circuits using different analysis techniques such as Mesh, Nodal, and Thevenin. | D8: =CONCATENATE(IF(F8=TRUE,"2",""),IF(AND(G8=TRUE,F8=TRUE),", ",""),IF(G8=TRUE,"3",""),IF(AND(H8=TRUE,COUNTIF(F8:G8,TRUE)>0),", ",""),IF(H8=TRUE,"6","")) -> 6 | E8: FALSE | F8: FALSE | G8: FALSE | H8: TRUE | I8: FALSE | J8: FALSE | K8: FALSE | M8: =IF(C8=0,"","Lectures, tutorial, and group discussions") -> Lectures, tutorial, and group discussions | N8: =IF(C8=0,"","HW assignments, quizzes, major exams, and final exam") -> HW assignments, quizzes, major exams, and final exam | BH8: =IF(E27=0,"",E27)
B9: 2.3 | C9: Analyze sinusoidal signals, reactance, admittance, and power using phasor forms. | D9: =CONCATENATE(IF(F9=TRUE,"2",""),IF(AND(G9=TRUE,F9=TRUE),", ",""),IF(G9=TRUE,"3",""),IF(AND(H9=TRUE,COUNTIF(F9:G9,TRUE)>0),", ",""),IF(H9=TRUE,"6","")) -> 6 | E9: FALSE | F9: FALSE | G9: FALSE | H9: TRUE | I9: FALSE | J9: FALSE | K9: FALSE | M9: =IF(C9=0,"","Lectures, tutorial, and group discussions") -> Lectures, tutorial, and group discussions | N9: =IF(C9=0,"","HW assignments, quizzes, major exams, and final exam") -> HW assignments, quizzes, major exams, and final exam | BH9: =IF(E28=0,"",E28)
D10: =CONCATENATE(IF(F10=TRUE,"2",""),IF(AND(G10=TRUE,F10=TRUE),", ",""),IF(G10=TRUE,"3",""),IF(AND(H10=TRUE,COUNTIF(F10:G10,TRUE)>0),", ",""),IF(H10=TRUE,"6","")) | E10: FALSE | F10: FALSE | G10: FALSE | H10: FALSE | I10: FALSE | J10: FALSE | K10: FALSE | M10: =IF(C10=0,"","Lectures, tutorial, and group discussions") | N10: =IF(C10=0,"","HW assignments, quizzes, major exams, and final exam") | BH10: =IF(E29=0,"",E29)
D11: =CONCATENATE(IF(F11=TRUE,"2",""),IF(AND(G11=TRUE,F11=TRUE),", ",""),IF(G11=TRUE,"3",""),IF(AND(H11=TRUE,COUNTIF(F11:G11,TRUE)>0),", ",""),IF(H11=TRUE,"6","")) | E11: FALSE | F11: FALSE | G11: FALSE | H11: FALSE | I11: FALSE | J11: FALSE | K11: FALSE | M11: =IF(C11=0,"","Lectures, tutorial, and group discussions") | N11: =IF(C11=0,"","HW assignments, quizzes, major exams, and final exam") | BH11: =IF(E30=0,"",E30) -> 90
A12: Values, autonomy and responsibility | B12: 3.1 | C12: Demonstrate DC/AC electric circuits using hardware boards and simulation in group activities. | D12: =CONCATENATE(IF(I12=TRUE,"4",""),IF(AND(J12=TRUE,I12=TRUE),", ",""),IF(J12=TRUE,"5",""),IF(AND(K12=TRUE,COUNTIF(I12:J12,TRUE)>0),", ",""),IF(K12=TRUE,"7","")) -> 5 | E12: FALSE | F12: FALSE | G12: FALSE | H12: FALSE | I12: FALSE | J12: TRUE | K12: FALSE | M12: =IF(C12=0,"","Lectures, tutorial, and group discussions") -> Lectures, tutorial, and group discussions | N12: =IF(C12=0,"","HW assignments, quizzes, major exams, and final exam") -> HW assignments, quizzes, major exams, and final exam
D13: =CONCATENATE(IF(I13=TRUE,"4",""),IF(AND(J13=TRUE,I13=TRUE),", ",""),IF(J13=TRUE,"5",""),IF(AND(K13=TRUE,COUNTIF(I13:J13,TRUE)>0),", ",""),IF(K13=TRUE,"7","")) | E13: FALSE | F13: FALSE | G13: FALSE | H13: FALSE | I13: FALSE | J13: FALSE | K13: FALSE | M13: =IF(C13=0,"","Lectures, tutorial, and group discussions") | N13: =IF(C13=0,"","HW assignments, quizzes, major exams, and final exam")
A14: Aligned PLOs | C14: =C2 -> Introduction to Circuits | D14: =A2 -> EE 201 | E14: =IF(COUNTIF($E$4:$E$13,TRUE)>0,$E$2,"") -> I | F14: =IF(COUNTIF($F$4:$F$13,TRUE)>0,$E$2,"") | G14: =IF(COUNTIF($G$4:$G$13,TRUE)>0,$E$2,"") | H14: =IF(COUNTIF($H$4:$H$13,TRUE)>0,$E$2,"") -> I | I14: =IF(COUNTIF($I$4:$I$13,TRUE)>0,$E$2,"") | J14: =IF(COUNTIF($J$4:$J$13,TRUE)>0,$E$2,"") -> I | K14: =IF(COUNTIF($K$4:$K$13,TRUE)>0,$E$2,"")
A15: Instructor | C15: Dr. Maged Esmail
A16: Course Description | B16: D1 | C16: This module provides a comprehensive introduction to both DC and AC circuit principles. Students will begin by reviewing fundamental concepts, including current, voltage, and power. The course then explores series and parallel circuits and delves into Ohm’s Law, Kirchhoff’s Laws, source transformations, bridge networks, and delta/star transformations. Key analysis methods and network theorems are also covered. Additionally, the module revisits inductors and capacitors, introduces sinusoidal sources and the concept of phasors, and details methods for analyzing AC circuits. Practical experience is emphasized through hands-on use of electrical measurement tools such as voltmeters, ammeters, wattmeters, function generators, and oscilloscopes.
A17: Textbook | B17: TB1 | C17: Robert L. Boylestad - Introductory Circuit Analysis (2016, Pearson), 13th Edition
A18: References | B18: R1
B19: R2
B20: R3
A21: Topics | B21: T1 | C21: Introduction, Basic concepts, charge, current, voltage, power, energy, resistance, and Ohm's Law, dissipated power. | D21: 10
B22: T2 | C22: Introduction, Series, Parallel and Series parallel circuits, Kirchhoff’s laws, voltage division and current distribution principles, voltage and current sources, open and short circuits | D22: 12
B23: T3 | C23: Mesh and Nodal Analysis, Bridge networks, Y-∆ and ∆-Y conversion | D23: 12
B24: T4 | C24: Superposition, Thevenin’s and Norton's theorems | D24: 12
B25: T5 | C25: Review of capacitance and inductance, Generation of AC voltages, parameters of AC. waveforms, average and effective (RMS) values | D25: 12
B26: T6 | C26: Review of complex number algebra, phasor representation, impedance and admittance. Capacitive and inductive reactance | D26: 12
B27: T7 | C27: Examples of analysis methods for AC circuits | D27: 10
B28: T8 | C28: General equation, Resistive circuit, Apparent Power, Inductive circuit and reactive power, Capacitive circuit, The power triangle, The total P, Q, and Power factor correction | D28: 10
B29: T9
B30: T10 | E30: =SUM(D21:D30) -> 90
A31: Objectives | B31: O1 | C31: Understand the basic linear electric circuits, theories, and concepts.
B32: O2 | C32: Understand circuit theorems and laws of circuit analysis in DC and AC circuits.
B33: O3 | C33: Gain hands-on experience and develop skills in using measurement tools like voltmeters, ammeters, and oscilloscopes while linking theory to practice.

Sheet EE 211
A1: Course Code: | B1: Id | C1: Course Title | D1: Type: | E1: Perf. Level: | F1: R/E: | G1: Credit Hours: | H1: Contact Hours: | I1: Pre-req.: | J1: Co-req.: | K1: Level | L1: Year | M1: Program | N1: Department | O1: Version | P1: Revision Date | Q1: COUNCIL /COMMITTEE | R1: REFERENCE NO. | S1: Date of Approval | T1: Instructor | U1: Course Description | V1: Textbook | W1: Ref. 1 | X1: Ref. 2 | Y1: Ref. 3 | Z1: CLO 1 | AA1: CLO 2 | AB1: CLO 3 | AC1: CLO 4 | AD1: CLO 5 | AE1: CLO 6 | AF1: CLO 7 | AG1: CLO 8 | AH1: CLO 9 | AI1: CLO 10 | AJ1: MPLO1 | AK1: MPLO2 | AL1: MPLO3 | AM1: MPLO4 | AN1: MPLO5 | AO1: MPLO6 | AP1: MPLO7 | AQ1: MPLO8 | AR1: MPLO9 | AS1: MPLO10 | AT1: Top1 | AU1: Top2 | AV1: Top3 | AW1: Top4 | AX1: Top5 | AY1: Top6 | AZ1: Top7 | BA1: Top8 | BB1: Top9 | BC1: Top10 | BD1: O1 | BE1: O2 | BF1: O3 | BG1: Top1 CH | BH1: Top2 CH | BI1: Top3 CH | BJ1: Top4 CH | BK1: Top5 CH | BL1: Top6 CH | BM1: Top7 CH | BN1: Top8 CH | BO1: Top9 CH | BP1: Top10 CH | BQ1: CLO 1 TS | BR1: CLO 2 TS | BS1: CLO 3 TS | BT1: CLO 4 TS | BU1: CLO 5 TS | BV1: CLO 6 TS | BW1: CLO 7 TS | BX1: CLO 8 TS | BY1: CLO 9 TS | BZ1: CLO 10 TS | CA1: CLO 1 AM | CB1: CLO 2 AM | CC1: CLO 3 AM | CD1: CLO 4 AM | CE1: CLO 5 AM | CF1: CLO 6 AM | CG1: CLO 7 AM | CH1: CLO 8 AM | CI1: CLO 9 AM | CJ1: CLO 10 AM | CK1: TotalCH | CL1: TutHrs | CM1: LabHrs | CN1: TopicHrs
A2: EE 211 | B2: 13 | C2: Electronic Fundamentals | D2: Program | E2: I | F2: Required | G2: 4 | H2: 6 | I2: EE 201 | J2: NA | K2: 4 | L2: 2 | M2: Electrical engineering | N2: Communications and Networks Engineering | O2: 1 | P2: 25-09-2024 | Q2: Departmental Council | R2: 1 | S2: 25-09-2024 | T2: =IF(C15=0,"",C15) -> Dr. Moustafa Nasralla | U2: =IF(C16=0,"",C16) -> This course provides a comprehensive introduction to essential semiconductor devices and amplifiers. It covers diodes, including special-purpose types, and explores Bipolar Junction Transistors (BJTs) with a focus on their operation, characteristics, and various biasing methods. Students will study transistor amplifier configurations such as common emitter, common collector, and common base, as well as classes of power amplifiers. The course also delves into operational amplifiers (Op-Amps), addressing their parameters, feedback mechanisms, and various practical circuit applications. | V2: =IF(C17=0,"",C17) -> Electronic Devices (Conventional Current Version): Pearson New International Edition, Author(s): Floyd, Thomas L., Publisher: Pearson (Intl), Edition: 9th, Pages: 952, Print ISBN: 9781292025643, 1292025646eText ISBN: 9781292038070 | W2: =IF(C18=0,"",C18) | X2: =IF(C19=0,"",C19) | Y2: =IF(C20=0,"",C20) | Z2: =IF(C4=0,"",C4) -> Describe the basic electronic circuits using diodes and transistors. | AA2: =IF(C5=0,"",C5) | AB2: =IF(C6=0,"",C6) | AC2: =IF(C7=0,"",C7) -> Analyze the characterstics of different BJT configurations and biasing circuits. | AD2: =IF(C8=0,"",C8) -> Analyze operational amplifier characterstics and circuits for different applications. | AE2: =IF(C9=0,"",C9) | AF2: =IF(C10=0,"",C10) | AG2: =IF(C11=0,"",C11) | AH2: =IF(C12=0,"",C12) -> Demonstrate experimentally basic electronic circuits and their applications | AI2: =IF(C13=0,"",C13) | AJ2: =D4 -> 1 | AK2: =D5 | AL2: =D6 | AM2: =D7 -> 6 | AN2: =D8 -> 6 | AO2: =D9 | AP2: =D10 | AQ2: =D11 | AR2: =D12 -> 5 | AS2: =D13 | AT2: =IF(C21=0,"",C21) -> Introduction Diodes and Applications, Special purpose diodes | AU2: =IF(C22=0,"",C22) -> Intro Bipolar Junction Transistor – BJT, BJT Operation | AV2: =IF(C23=0,"",C23) -> Stabilization, Voltage divider bias method | AW2: =IF(C24=0,"",C24) -> Ch/cs curves, modes of operation, load lines, Ratings, Q-Point, BJT applications | AX2: =IF(C25=0,"",C25) -> Basic of Amplifier AC parameters - Transistor AC Models | AY2: =IF(C26=0,"",C26) -> Classes of Power amplifiers | AZ2: =IF(C27=0,"",C27) -> Introduction to Operational Amplifiers Parameters | BA2: =IF(C28=0,"",C28) -> Op-Amps: Inverting and non-inverting amplifier, | BB2: =IF(C29=0,"",C29) | BC2: =IF(C30=0,"",C30) | BD2: =C31 -> Understand diode and BJT fundamentals and applications. | BE2: =C32 -> Analyze and design various transistor amplifier configurations. | BF2: =C33 -> Master operational amplifier parameters and feedback effects. | BG2: =IF($D21=0,"",$D21) -> 12 | BH2: =IF($D22=0,"",$D22) -> 12 | BI2: =IF($D23=0,"",$D23) -> 12 | BJ2: =IF($D24=0,"",$D24) -> 9 | BK2: =IF($D25=0,"",$D25) -> 9 | BL2: =IF($D26=0,"",$D26) -> 12 | BM2: =IF($D27=0,"",$D27) -> 12 | BN2: =IF($D28=0,"",$D28) -> 12 | BO2: =IF($D29=0,"",$D29) | BP2: =IF($D30=0,"",$D30) | BQ2: =IF($M4=0,"",$M4) -> Lectures, tutorials, group discussions | BR2: =IF($M5=0,"",$M5) | BS2: =IF($M6=0,"",$M6) | BT2: =IF($M7=0,"",$M7) -> Lectures, tutorial, and group discussions | BU2: =IF($M8=0,"",$M8) -> Lectures, tutorial, and group discussions | BV2: =IF($M9=0,"",$M9) | BW2: =IF($M10=0,"",$M10) | BX2: =IF($M11=0,"",$M11) | BY2: =IF($M12=0,"",$M12) -> Lectures, tutorial, and group discussions | BZ2: =IF($M13=0,"",$M13) | CA2: =IF($N4=0,"",$N4) -> HW assignments, quizzes, major exams, and final exam | CB2: =IF($N5=0,"",$N5) | CC2: =IF($N6=0,"",$N6) | CD2: =IF($N7=0,"",$N7) -> HW assignments, quizzes, major exams, and final exam | CE2: =IF($N8=0,"",$N8) -> HW assignments, quizzes, major exams, and final exam | CF2: =IF($N9=0,"",$N9) | CG2: =IF($N10=0,"",$N10) | CH2: =IF($N11=0,"",$N11) | CI2: =IF($N12=0,"",$N12) -> HW assignments, quizzes, major exams, and final exam | CJ2: =IF($N13=0,"",$N13) | CK2: =H2*15 -> 90 | CL2: =IF(H2>3,15,"") -> 15 | CM2: =IF(G2=4,30,"") -> 30 | CN2: =E30 -> 90
A3: Course Learning Outcomes | D3: Aligned PLOs | E3: PLO1 | F3: PLO2 | G3: PLO3 | H3: PLO6 | I3: PLO4 | J3: PLO5 | K3: PLO7 | M3: Teaching Strategy | N3: Assessment Method | BH3: =IF(E22=0,"",E22)
A4: Knowledge and understanding | B4: 1.1 | C4: Describe the basic electronic circuits using diodes and transistors. | D4: =IF(E4=TRUE,"1","") -> 1 | E4: TRUE | F4: FALSE | G4: FALSE | H4: FALSE | I4: FALSE | J4: FALSE | K4: FALSE | M4: =IF(C4=0,"","Lectures, tutorials, group discussions") -> Lectures, tutorials, group discussions | N4: =IF(C4=0,"","HW assignments, quizzes, major exams, and final exam") -> HW assignments, quizzes, major exams, and final exam | BH4: =IF(E23=0,"",E23)
D5: =IF(E5=TRUE,"1","") | E5: FALSE | F5: FALSE | G5: FALSE | H5: FALSE | I5: FALSE | J5: FALSE | K5: FALSE | M5: =IF(C5=0,"","Lectures, tutorial, and group discussions") | N5: =IF(C5=0,"","HW assignments, quizzes, major exams, and final exam") | BH5: =IF(E24=0,"",E24)
D6: =IF(E6=TRUE,"1","") | E6: FALSE | F6: FALSE | G6: FALSE | H6: FALSE | I6: FALSE | J6: FALSE | K6: FALSE | M6: =IF(C6=0,"","Lectures, tutorial, and group discussions") | N6: =IF(C6=0,"","HW assignments, quizzes, major exams, and final exam") | BH6: =IF(E25=0,"",E25)
A7: Skills | B7: 2.1 | C7: Analyze the characterstics of different BJT configurations and biasing circuits. | D7: =CONCATENATE(IF(F7=TRUE,"2",""),IF(AND(G7=TRUE,F7=TRUE),", ",""),IF(G7=TRUE,"3",""),IF(AND(H7=TRUE,COUNTIF(F7:G7,TRUE)>0),", ",""),IF(H7=TRUE,"6","")) -> 6 | E7: FALSE | F7: FALSE | G7: FALSE | H7: TRUE | I7: FALSE | J7: FALSE | K7: FALSE | M7: =IF(C7=0,"","Lectures, tutorial, and group discussions") -> Lectures, tutorial, and group discussions | N7: =IF(C7=0,"","HW assignments, quizzes, major exams, and final exam") -> HW assignments, quizzes, major exams, and final exam | BH7: =IF(E26=0,"",E26)
B8: 2.2 | C8: Analyze operational amplifier characterstics and circuits for different applications. | D8: =CONCATENATE(IF(F8=TRUE,"2",""),IF(AND(G8=TRUE,F8=TRUE),", ",""),IF(G8=TRUE,"3",""),IF(AND(H8=TRUE,COUNTIF(F8:G8,TRUE)>0),", ",""),IF(H8=TRUE,"6","")) -> 6 | E8: FALSE | F8: FALSE | G8: FALSE | H8: TRUE | I8: FALSE | J8: FALSE | K8: FALSE | M8: =IF(C8=0,"","Lectures, tutorial, and group discussions") -> Lectures, tutorial, and group discussions | N8: =IF(C8=0,"","HW assignments, quizzes, major exams, and final exam") -> HW assignments, quizzes, major exams, and final exam | BH8: =IF(E27=0,"",E27)
D9: =CONCATENATE(IF(F9=TRUE,"2",""),IF(AND(G9=TRUE,F9=TRUE),", ",""),IF(G9=TRUE,"3",""),IF(AND(H9=TRUE,COUNTIF(F9:G9,TRUE)>0),", ",""),IF(H9=TRUE,"6","")) | E9: FALSE | F9: FALSE | G9: FALSE | H9: FALSE | I9: FALSE | J9: FALSE | K9: FALSE | M9: =IF(C9=0,"","Lectures, tutorial, and group discussions") | N9: =IF(C9=0,"","HW assignments, quizzes, major exams, and final exam") | BH9: =IF(E28=0,"",E28)
D10: =CONCATENATE(IF(F10=TRUE,"2",""),IF(AND(G10=TRUE,F10=TRUE),", ",""),IF(G10=TRUE,"3",""),IF(AND(H10=TRUE,COUNTIF(F10:G10,TRUE)>0),", ",""),IF(H10=TRUE,"6","")) | E10: FALSE | F10: FALSE | G10: FALSE | H10: FALSE | I10: FALSE | J10: FALSE | K10: FALSE | M10: =IF(C10=0,"","Lectures, tutorial, and group discussions") | N10: =IF(C10=0,"","HW assignments, quizzes, major exams, and final exam") | BH10: =IF(E29=0,"",E29)
D11: =CONCATENATE(IF(F11=TRUE,"2",""),IF(AND(G11=TRUE,F11=TRUE),", ",""),IF(G11=TRUE,"3",""),IF(AND(H11=TRUE,COUNTIF(F11:G11,TRUE)>0),", ",""),IF(H11=TRUE,"6","")) | E11: FALSE | F11: FALSE | G11: FALSE | H11: FALSE | I11: FALSE | J11: FALSE | K11: FALSE | M11: =IF(C11=0,"","Lectures, tutorial, and group discussions") | N11: =IF(C11=0,"","HW assignments, quizzes, major exams, and final exam") | BH11: =IF(E30=0,"",E30) -> 90
A12: Values, autonomy and responsibility | B12: 3.1 | C12: Demonstrate experimentally basic electronic circuits and their applications | D12: =CONCATENATE(IF(I12=TRUE,"4",""),IF(AND(J12=TRUE,I12=TRUE),", ",""),IF(J12=TRUE,"5",""),IF(AND(K12=TRUE,COUNTIF(I12:J12,TRUE)>0),", ",""),IF(K12=TRUE,"7","")) -> 5 | E12: FALSE | F12: FALSE | G12: FALSE | H12: FALSE | I12: FALSE | J12: TRUE | K12: FALSE | M12: =IF(C12=0,"","Lectures, tutorial, and group discussions") -> Lectures, tutorial, and group discussions | N12: =IF(C12=0,"","HW assignments, quizzes, major exams, and final exam") -> HW assignments, quizzes, major exams, and final exam
D13: =CONCATENATE(IF(I13=TRUE,"4",""),IF(AND(J13=TRUE,I13=TRUE),", ",""),IF(J13=TRUE,"5",""),IF(AND(K13=TRUE,COUNTIF(I13:J13,TRUE)>0),", ",""),IF(K13=TRUE,"7","")) | E13: FALSE | F13: FALSE | G13: FALSE | H13: FALSE | I13: FALSE | J13: FALSE | K13: FALSE | M13: =IF(C13=0,"","Lectures, tutorial, and group discussions") | N13: =IF(C13=0,"","HW assignments, quizzes, major exams, and final exam")
A14: Aligned PLOs | C14: =C2 -> Electronic Fundamentals | D14: =A2 -> EE 211 | E14: =IF(COUNTIF($E$4:$E$13,TRUE)>0,$E$2,"") -> I | F14: =IF(COUNTIF($F$4:$F$13,TRUE)>0,$E$2,"") | G14: =IF(COUNTIF($G$4:$G$13,TRUE)>0,$E$2,"") | H14: =IF(COUNTIF($H$4:$H$13,TRUE)>0,$E$2,"") -> I | I14: =IF(COUNTIF($I$4:$I$13,TRUE)>0,$E$2,"") | J14: =IF(COUNTIF($J$4:$J$13,TRUE)>0,$E$2,"") -> I | K14: =IF(COUNTIF($K$4:$K$13,TRUE)>0,$E$2,"")
A15: Instructor | C15: Dr. Moustafa Nasralla
A16: Course Description | B16: D1 | C16: This course provides a comprehensive introduction to essential semiconductor devices and amplifiers. It covers diodes, including special-purpose types, and explores Bipolar Junction Transistors (BJTs) with a focus on their operation, characteristics, and various biasing methods. Students will study transistor amplifier configurations such as common emitter, common collector, and common base, as well as classes of power amplifiers. The course also delves into operational amplifiers (Op-Amps), addressing their parameters, feedback mechanisms, and various practical circuit applications.
A17: Textbook | B17: TB1 | C17: Electronic Devices (Conventional Current Version): Pearson New International Edition, Author(s): Floyd, Thomas L., Publisher: Pearson (Intl), Edition: 9th, Pages: 952, Print ISBN: 9781292025643, 1292025646eText ISBN: 9781292038070
A18: References | B18: R1
B19: R2
B20: R3
A21: Topics | B21: T1 | C21: Introduction Diodes and Applications, Special purpose diodes | D21: 12
B22: T2 | C22: Intro Bipolar Junction Transistor – BJT, BJT Operation | D22: 12
B23: T3 | C23: Stabilization, Voltage divider bias method | D23: 12
B24: T4 | C24: Ch/cs curves, modes of operation, load lines, Ratings, Q-Point, BJT applications | D24: 9
B25: T5 | C25: Basic of Amplifier AC parameters - Transistor AC Models | D25: 9
B26: T6 | C26: Classes of Power amplifiers | D26: 12
B27: T7 | C27: Introduction to Operational Amplifiers Parameters | D27: 12
B28: T8 | C28: Op-Amps: Inverting and non-inverting amplifier, | D28: 12
B29: T9
B30: T10 | E30: =SUM(D21:D30) -> 90
A31: Objectives | B31: O1 | C31: Understand diode and BJT fundamentals and applications.
